Workbook

Sheet Planilha1
A1: TAREFA | B1: SETOR | C1: ATIVIDADE | D1: ATRIBUÍDO PARA | E1: Minutos | F1: Horas
A2: 2 - LIMPEZA INICIAL | B2: PREPARAÇÃO | C2: Aspiração detalhada | D2: Lohan | E2: 25 | F2: 0.41666667
A3: 3 - ISOLANTE OU FELTRO | B3: PREPARAÇÃO | C3: Aplicar isolante no teto | D3: Lohan | E3: 90 | F3: 1.5
A4: 3 - ISOLANTE OU FELTRO | B4: PREPARAÇÃO | C4: Aplicar isolante no assoalho | D4: Lohan | E4: 90 | F4: 1.5
A5: 3 - ISOLANTE OU FELTRO | B5: PREPARAÇÃO | C5: Aplicar feltro no teto | D5: Lohan | E5: 60 | F5: 1
A6: 3 - ISOLANTE OU FELTRO | B6: PREPARAÇÃO | C6: Colagem do feltro no assoalho | D6: Lohan | E6: 40 | F6: 0.66666667
A7: 3 - ISOLANTE OU FELTRO | B7: APLICAÇÃO COLA | C7: Aplicar cola no feltro | D7: Lohan | E7: 20 | F7: 0.33333333
A8: 6 - CARPETE / ASSOALHO ( NOVO ? / MOLDADO ? / PORSCHE ?) | B8: PREPARAÇÃO | C8: 0 | D8: Lohan | E8: 0 | F8: 0
A9: 6 - CARPETE / ASSOALHO ( NOVO ? / MOLDADO ? / PORSCHE ?) | B9: PREPARAÇÃO | C9: 0 | D9: Lohan | E9: 0 | F9: 0
A10: 9 - TAMPA TRASEIRA | B10: APLICAÇÃO COLA | C10: Aplicar cola | D10: Lohan | E10: 15 | F10: 0.25
A11: 9 - TAMPA TRASEIRA | B11: PREPARAÇÃO | C11: Limpar e inspecionar | D11: Lohan | E11: 15 | F11: 0.25
A12: 9 - TAMPA TRASEIRA | B12: PREPARAÇÃO | C12: Raspar/Lixar | D12: Lohan | E12: 60 | F12: 1
A13: 9 - TAMPA TRASEIRA | B13: DESMONTAGEM | C13: Desmontar peça para preparação | D13: Lohan | E13: 10 | F13: 0.16666667
A14: 10 - LATERAIS TRASEIRAS | B14: PREPARAÇÃO | C14: reparo estrutural | D14: Lohan | E14: 10 | F14: 0.16666667
A15: 10 - LATERAIS TRASEIRAS | B15: PREPARAÇÃO | C15: Limpar e inspecionar | D15: Lohan | E15: 10 | F15: 0.16666667
A16: 10 - LATERAIS TRASEIRAS | B16: PREPARAÇÃO | C16: raspar/lixar | D16: Lohan | E16: 160 | F16: 2.6666667
A17: 10 - LATERAIS TRASEIRAS | B17: PREPARAÇÃO | C17: remoção do tecido/courvin para a preparação | D17: Lohan | E17: 10 | F17: 0.16666667

Sheet GERENCIAMENTO
A1: Gestão de Ordem de Serviço (OS)
B3: # OS: | C3: 7945
B5: Veículo: | C5: gol gti | E5: Atualizado em: | F5: 45544
B7: Lider do Projeto: | C7: Paulique
B9: Início do projeto: | C9: 45544 | F9: Horas Alvo: | G9: =GETPIVOTDATA("Horas",$E$22) -> 57.416667
B11: Data entrega ao Cliente: | C11: 45569 | F11: Horas Reais: | G11: =GETPIVOTDATA("H Real",'PRG02'!$A$3) -> 10.916667
B13: Dias Para Entrega: | C13: =C11-(TODAY()) -> -1 | F13: GAP em Horas: | G13: =G9-G11 -> 46.5
F15: Progresso da OS: | G15: =AVERAGE(C23:C42) -> 0.094375
F17: Eficiência: | G17: =GETPIVOTDATA("Média de Campo2",'PRG02'!$A$3) -> 0.13804004
F19: GAP Horas Vendidas: | G19: =(G9-G11)/G9 -> 0.80986938
A21: Missão a ser realizada selecionada abaixo: | E21: PLANEJAMENTO DE EXECUÇÃO
C22: % concluído | E22: Distribuição | F22: Colaboradores
A23: x | B23: 1 - RETIRADA DE PEÇAS DO VEÍCULO/BALCÃO | C23: =GETPIVOTDATA("Média de % Conclusão",'PRG02'!$A$3,"TAREFA","1 - RETIRADA DE PEÇAS DO VEÍCULO/BALCÃO") -> 0.8875 | D23: =IF(A23="x",B23,0) -> 1 - RETIRADA DE PEÇAS DO VEÍCULO/BALCÃO | E23: Tarefas | F23: Brea | G23: Gabriel | H23: Arthur | I23: Edna | J23: Rita | K23: Kadu | L23: Lohan | M23: Nikolas | N23: Paulique | O23: Não Executar | P23: Total Geral
A24: x | B24: 2 - LIMPEZA INICIAL | C24: =GETPIVOTDATA("Média de % Conclusão",'PRG02'!$A$3,"TAREFA","2 - LIMPEZA INICIAL") -> 1 | D24: =IF(A24="x",B24,0) -> 2 - LIMPEZA INICIAL | E24: 1 - RETIRADA DE PEÇAS DO VEÍCULO/BALCÃO | F24: 0.25 | K24: 0.75 | M24: 2.4166667 | O24: 0 | P24: 3.4166667
A25: x | B25: 3 - ISOLANTE OU FELTRO | C25: =GETPIVOTDATA("Média de % Conclusão",'PRG02'!$A$3,"TAREFA","3 - ISOLANTE OU FELTRO") -> 0 | D25: =IF(A25="x",B25,0) -> 3 - ISOLANTE OU FELTRO | E25: 2 - LIMPEZA INICIAL | L25: 0.41666667 | O25: 0 | P25: 0.41666667
A26: x | B26: 4 - TETO | C26: =GETPIVOTDATA("Média de % Conclusão",'PRG02'!$A$3,"TAREFA","4 - TETO") -> 0 | D26: =IF(A26="x",B26,0) -> 4 - TETO | E26: 3 - ISOLANTE OU FELTRO | J26: 0.75 | L26: 5 | O26: 0 | P26: 5.75
A27: x | B27: 5 - CINTOS | C27: =GETPIVOTDATA("Média de % Conclusão",'PRG02'!$A$3,"TAREFA","5 - CINTOS") -> 0 | D27: =IF(A27="x",B27,0) -> 5 - CINTOS | E27: 4 - TETO | G27: 1.3333333 | H27: 1.3333333 | J27: 0.25 | M27: 6.8333333 | O27: 0 | P27: 9.75
A28: x | B28: 6 - CARPETE / ASSOALHO ( NOVO ? / MOLDADO ? / PORSCHE ?) | C28: =GETPIVOTDATA("Média de % Conclusão",'PRG02'!$A$3,"TAREFA","6 - CARPETE / ASSOALHO ( NOVO ? / MOLDADO ? / PORSCHE ?)") -> 0 | D28: =IF(A28="x",B28,0) -> 6 - CARPETE / ASSOALHO ( NOVO ? / MOLDADO ? / PORSCHE ?) | E28: 5 - CINTOS | H28: 0.41666667 | O28: 0 | P28: 0.41666667
A29: x | B29: 7 - CONSOLE CENTRAL + PEÇAS | C29: =GETPIVOTDATA("Média de % Conclusão",'PRG02'!$A$3,"TAREFA","7 - CONSOLE CENTRAL + PEÇAS") -> 0 | D29: =IF(A29="x",B29,0) -> 7 - CONSOLE CENTRAL + PEÇAS | E29: 6 - CARPETE / ASSOALHO ( NOVO ? / MOLDADO ? / PORSCHE ?) | H29: 1 | I29: 0 | L29: 0 | O29: 0 | P29: 1
A30: x | B30: 8 - PORTA MALAS | C30: =GETPIVOTDATA("Média de % Conclusão",'PRG02'!$A$3,"TAREFA","8 - PORTA MALAS") -> 0 | D30: =IF(A30="x",B30,0) -> 8 - PORTA MALAS | E30: 7 - CONSOLE CENTRAL + PEÇAS | H30: 0.33333333 | O30: 0 | P30: 0.33333333
A31: x | B31: 9 - TAMPA TRASEIRA | C31: =GETPIVOTDATA("Média de % Conclusão",'PRG02'!$A$3,"TAREFA","9 - TAMPA TRASEIRA") -> 0 | D31: =IF(A31="x",B31,0) -> 9 - TAMPA TRASEIRA | E31: 8 - PORTA MALAS | G31: 0.66666667 | H31: 1.8333333 | J31: 0.5 | K31: 0.083333333 | O31: 0 | P31: 3.0833333
A32: x | B32: 10 - LATERAIS TRASEIRAS | C32: =GETPIVOTDATA("Média de % Conclusão",'PRG02'!$A$3,"TAREFA","10 - LATERAIS TRASEIRAS") -> 0 | D32: =IF(A32="x",B32,0) -> 10 - LATERAIS TRASEIRAS | E32: 9 - TAMPA TRASEIRA | G32: 0.66666667 | J32: 0.16666667 | K32: 0.33333333 | L32: 1.6666667 | O32: 0 | P32: 2.8333333
A33: x | B33: 11 - OMBREIRA | C33: =GETPIVOTDATA("Média de % Conclusão",'PRG02'!$A$3,"TAREFA","11 - OMBREIRA") -> 0 | D33: =IF(A33="x",B33,0) -> 11 - OMBREIRA | E33: 10 - LATERAIS TRASEIRAS | G33: 1 | J33: 0.25 | K33: 0.66666667 | L33: 3.1666667 | O33: 0 | P33: 5.0833333
B34: 12 - FORROS DE PORTAS | C34: =GETPIVOTDATA("Média de % Conclusão",'PRG02'!$A$3,"TAREFA","12 - FORROS DE PORTAS") -> 0 | D34: =IF(A34="x",B34,0) -> 0 | E34: 11 - OMBREIRA | G34: 0.91666667 | H34: 1.5 | J34: 0.16666667 | M34: 2.3333333 | O34: 0 | P34: 4.9166667
B35: 13 - ACABAMENTOS | C35: =GETPIVOTDATA("Média de % Conclusão",'PRG02'!$A$3,"TAREFA","13 - ACABAMENTOS") -> 0 | D35: =IF(A35="x",B35,0) -> 0 | E35: 15 - BANCOS DIANTEIROS | I35: 4.5 | J35: 1.5 | K35: 6.6666667 | L35: 2.5833333 | N35: 1 | O35: 0 | P35: 16.25
B36: 14 - BANCOS TRASEIROS | C36: =GETPIVOTDATA("Média de % Conclusão",'PRG02'!$A$3,"TAREFA","14 - BANCOS TRASEIROS") -> 0 | D36: =IF(A36="x",B36,0) -> 0 | E36: 16 - VOLANTE | I36: 1.5 | J36: 1.8333333 | L36: 0.5 | M36: 0.33333333 | O36: 0 | P36: 4.1666667
A37: x | B37: 15 - BANCOS DIANTEIROS | C37: =GETPIVOTDATA("Média de % Conclusão",'PRG02'!$A$3,"TAREFA","15 - BANCOS DIANTEIROS") -> 0 | D37: =IF(A37="x",B37,0) -> 15 - BANCOS DIANTEIROS | E37: Total Geral | F37: 0.25 | G37: 4.5833333 | H37: 6.4166667 | I37: 6 | J37: 5.4166667 | K37: 8.5 | L37: 13.333333 | M37: 11.916667 | N37: 1 | O37: 0 | P37: 57.416667
A38: x | B38: 16 - VOLANTE | C38: =GETPIVOTDATA("Média de % Conclusão",'PRG02'!$A$3,"TAREFA","16 - VOLANTE") -> 0 | D38: =IF(A38="x",B38,0) -> 16 - VOLANTE
B39: 17 - TAMPÃO | C39: =GETPIVOTDATA("Média de % Conclusão",'PRG02'!$A$3,"TAREFA","17 - TAMPÃO") -> 0 | D39: =IF(A39="x",B39,0) -> 0
B40: 18 - MONTAGEM VEÍCULO | C40: =GETPIVOTDATA("Média de % Conclusão",'PRG02'!$A$3,"TAREFA","18 - MONTAGEM VEÍCULO") -> 0 | D40: =IF(A40="x",B40,0) -> 0
B41: 19 - LIMPEZA FINAL | C41: =GETPIVOTDATA("Média de % Conclusão",'PRG02'!$A$3,"TAREFA","19 - LIMPEZA FINAL") -> 0 | D41: =IF(A41="x",B41,0) -> 0
B42: 20 - INPEÇÃO DE QUALIDADE | C42: =GETPIVOTDATA("Média de % Conclusão",'PRG02'!$A$3,"TAREFA","20 - INPEÇÃO DE QUALIDADE") -> 0 | D42: =IF(A42="x",B42,0) -> 0
E50: Colaborador | F50: Hora Prevista | G50: Hora Real | H50: Eficiência
E51: Gabriel | F51: 7.5 | G51: 0 | H51: 0
E52: Brea | F52: 0.33333333 | G52: 0.25 | H52: 0.75
E53: Arthur | F53: 14.833333 | G53: 0 | H53: 0
E54: Edna | F54: 7 | G54: 0 | H54: 0
E55: Rita | F55: 7.3333333 | G55: 1.5 | H55: 0.20454545
E56: Lohan | F56: 13.583333 | G56: 0.83333333 | H56: 0.061349693
E57: Nikolas | F57: 14.416667 | G57: 7.4166667 | H57: 0.51445087
...

Sheet ATIVIDADES E APONTAMENTOS
A1: AUXILIAR | B1: TAREFA | C1: SETOR | D1: ATIVIDADE | E1: ATRIBUÍDO PARA | F1: Tempo Previsto (min) | G1: Tempo Real (min | H1: % Conclusão
A2: =B2&COUNTIF($B$2:B2,B2) -> 1 - RETIRADA DE PEÇAS DO VEÍCULO/BALCÃO1 | B2: 1 - RETIRADA DE PEÇAS DO VEÍCULO/BALCÃO | C2: DESMONTAGEM | D2: Verificar se não tem nenhuma peça quebrada ou faltante, riscos externos e internos (Checklist durante desmontagem (Foto/Filmagem) | E2: Kadu | F2: 15 | G2: 15 | H2: 1
A3: =B3&COUNTIF($B$2:B3,B3) -> 1 - RETIRADA DE PEÇAS DO VEÍCULO/BALCÃO2 | B3: 1 - RETIRADA DE PEÇAS DO VEÍCULO/BALCÃO | C3: DESMONTAGEM | D3: Retirada do volante (se necessário) | E3: Kadu | F3: 20 | G3: 20 | H3: 1
A4: =B4&COUNTIF($B$2:B4,B4) -> 1 - RETIRADA DE PEÇAS DO VEÍCULO/BALCÃO3 | B4: 1 - RETIRADA DE PEÇAS DO VEÍCULO/BALCÃO | C4: DESMONTAGEM | D4: Retirar bancos D/T | E4: Kadu | F4: 10 | G4: 20 | H4: 1
A5: =B5&COUNTIF($B$2:B5,B5) -> 1 - RETIRADA DE PEÇAS DO VEÍCULO/BALCÃO4 | B5: 1 - RETIRADA DE PEÇAS DO VEÍCULO/BALCÃO | C5: DESMONTAGEM | D5: Retirar Laterais D/T + Ombreiras | E5: Brea | F5: 15 | G5: 15 | H5: 1
A6: =B6&COUNTIF($B$2:B6,B6) -> 1 - RETIRADA DE PEÇAS DO VEÍCULO/BALCÃO5 | B6: 1 - RETIRADA DE PEÇAS DO VEÍCULO/BALCÃO | C6: DESMONTAGEM | D6: Retirar console + carpete do assoalho | E6: =VLOOKUP(C6,Colaboradores!$E$2:$G$33,2,FALSE) -> Nikolas | F6: 40 | G6: 40 | H6: 1
A7: =B7&COUNTIF($B$2:B7,B7) -> 1 - RETIRADA DE PEÇAS DO VEÍCULO/BALCÃO6 | B7: 1 - RETIRADA DE PEÇAS DO VEÍCULO/BALCÃO | C7: DESMONTAGEM | D7: Retirada da lateral do porta-malas | E7: =VLOOKUP(C7,Colaboradores!$E$2:$G$33,2,FALSE) -> Nikolas | F7: 15 | G7: 15 | H7: 0.1
A8: =B8&COUNTIF($B$2:B8,B8) -> 1 - RETIRADA DE PEÇAS DO VEÍCULO/BALCÃO7 | B8: 1 - RETIRADA DE PEÇAS DO VEÍCULO/BALCÃO | C8: DESMONTAGEM | D8: Retirada do carpete da caixa de rodas +chão do porta-malas e prateleiras do tampão. | E8: =VLOOKUP(C8,Colaboradores!$E$2:$G$33,2,FALSE) -> Nikolas | F8: 30 | G8: 330 | H8: 1
A9: =B9&COUNTIF($B$2:B9,B9) -> 1 - RETIRADA DE PEÇAS DO VEÍCULO/BALCÃO8 | B9: 1 - RETIRADA DE PEÇAS DO VEÍCULO/BALCÃO | C9: DESMONTAGEM | D9: Retirada do teto + acessórios e colunas. | E9: =VLOOKUP(C9,Colaboradores!$E$2:$G$33,2,FALSE) -> Nikolas | F9: 60 | G9: 60 | H9: 1
A10: =B10&COUNTIF($B$2:B10,B10) -> 1 - RETIRADA DE PEÇAS DO VEÍCULO/BALCÃO9 | B10: 1 - RETIRADA DE PEÇAS DO VEÍCULO/BALCÃO | E10: =VLOOKUP(C10,Colaboradores!$E$2:$G$33,2,FALSE) -> #N/A
A11: =B11&COUNTIF($B$2:B11,B11) -> 1 - RETIRADA DE PEÇAS DO VEÍCULO/BALCÃO10 | B11: 1 - RETIRADA DE PEÇAS DO VEÍCULO/BALCÃO | E11: =VLOOKUP(C11,Colaboradores!$E$2:$G$33,2,FALSE) -> #N/A
A12: =B12&COUNTIF($B$2:B12,B12) -> 1 - RETIRADA DE PEÇAS DO VEÍCULO/BALCÃO11 | B12: 1 - RETIRADA DE PEÇAS DO VEÍCULO/BALCÃO | E12: =VLOOKUP(C12,Colaboradores!$E$2:$G$33,2,FALSE) -> #N/A
A13: =B13&COUNTIF($B$2:B13,B13) -> 1 - RETIRADA DE PEÇAS DO VEÍCULO/BALCÃO12 | B13: 1 - RETIRADA DE PEÇAS DO VEÍCULO/BALCÃO | E13: =VLOOKUP(C13,Colaboradores!$E$2:$G$33,2,FALSE) -> #N/A
A14: =B14&COUNTIF($B$2:B14,B14) -> 1 - RETIRADA DE PEÇAS DO VEÍCULO/BALCÃO13 | B14: 1 - RETIRADA DE PEÇAS DO VEÍCULO/BALCÃO | E14: =VLOOKUP(C14,Colaboradores!$E$2:$G$33,2,FALSE) -> #N/A
A15: =B15&COUNTIF($B$2:B15,B15) -> 1 - RETIRADA DE PEÇAS DO VEÍCULO/BALCÃO14 | B15: 1 - RETIRADA DE PEÇAS DO VEÍCULO/BALCÃO | E15: =VLOOKUP(C15,Colaboradores!$E$2:$G$33,2,FALSE) -> #N/A
A16: =B16&COUNTIF($B$2:B16,B16) -> 2 - LIMPEZA INICIAL1 | B16: 2 - LIMPEZA INICIAL | C16: PREPARAÇÃO | D16: Aspiração detalhada | E16: Lohan | F16: 25 | G16: 50 | H16: 1
A17: =B17&COUNTIF($B$2:B17,B17) -> 2 - LIMPEZA INICIAL2 | B17: 2 - LIMPEZA INICIAL | E17: =VLOOKUP(C17,Colaboradores!$E$2:$G$33,2,FALSE) -> #N/A
A18: =B18&COUNTIF($B$2:B18,B18) -> 2 - LIMPEZA INICIAL3 | B18: 2 - LIMPEZA INICIAL | E18: =VLOOKUP(C18,Colaboradores!$E$2:$G$33,2,FALSE) -> #N/A
A19: =B19&COUNTIF($B$2:B19,B19) -> 2 - LIMPEZA INICIAL4 | B19: 2 - LIMPEZA INICIAL | E19: =VLOOKUP(C19,Colaboradores!$E$2:$G$33,2,FALSE) -> #N/A
A20: =B20&COUNTIF($B$2:B20,B20) -> 2 - LIMPEZA INICIAL5 | B20: 2 - LIMPEZA INICIAL | E20: =VLOOKUP(C20,Colaboradores!$E$2:$G$33,2,FALSE) -> #N/A
A21: =B21&COUNTIF($B$2:B21,B21) -> 2 - LIMPEZA INICIAL6 | B21: 2 - LIMPEZA INICIAL | E21: =VLOOKUP(C21,Colaboradores!$E$2:$G$33,2,FALSE) -> #N/A
A22: =B22&COUNTIF($B$2:B22,B22) -> 2 - LIMPEZA INICIAL7 | B22: 2 - LIMPEZA INICIAL | E22: =VLOOKUP(C22,Colaboradores!$E$2:$G$33,2,FALSE) -> #N/A
A23: =B23&COUNTIF($B$2:B23,B23) -> 2 - LIMPEZA INICIAL8 | B23: 2 - LIMPEZA INICIAL | E23: =VLOOKUP(C23,Colaboradores!$E$2:$G$33,2,FALSE) -> #N/A
A24: =B24&COUNTIF($B$2:B24,B24) -> 3 - ISOLANTE OU FELTRO1 | B24: 3 - ISOLANTE OU FELTRO | C24: CORTE | D24: Cortar Feltro seguindo molde assoalho | E24: =VLOOKUP(C24,Colaboradores!$E$2:$G$33,2,FALSE) -> Rita | F24: 45 | G24: 90 | H24: 0
A25: =B25&COUNTIF($B$2:B25,B25) -> 3 - ISOLANTE OU FELTRO2 | B25: 3 - ISOLANTE OU FELTRO | C25: APLICAÇÃO COLA | D25: Aplicar cola no feltro | E25: =VLOOKUP(C25,Colaboradores!$E$2:$G$33,2,FALSE) -> Lohan | F25: 20 | H25: 0
A26: =B26&COUNTIF($B$2:B26,B26) -> 3 - ISOLANTE OU FELTRO3 | B26: 3 - ISOLANTE OU FELTRO | C26: PREPARAÇÃO | D26: Colagem do feltro no assoalho | E26: Lohan | F26: 40 | H26: 0
A27: =B27&COUNTIF($B$2:B27,B27) -> 3 - ISOLANTE OU FELTRO4 | B27: 3 - ISOLANTE OU FELTRO | C27: PREPARAÇÃO | D27: Aplicar feltro no teto | E27: Lohan | F27: 60 | H27: 0
A28: =B28&COUNTIF($B$2:B28,B28) -> 3 - ISOLANTE OU FELTRO5 | B28: 3 - ISOLANTE OU FELTRO | C28: PREPARAÇÃO | D28: Aplicar isolante no assoalho | E28: Lohan | F28: 90 | H28: 0
A29: =B29&COUNTIF($B$2:B29,B29) -> 3 - ISOLANTE OU FELTRO6 | B29: 3 - ISOLANTE OU FELTRO | C29: PREPARAÇÃO | D29: Aplicar isolante no teto | E29: Lohan | F29: 90 | H29: 0
A30: =B30&COUNTIF($B$2:B30,B30) -> 3 - ISOLANTE OU FELTRO7 | B30: 3 - ISOLANTE OU FELTRO | E30: =VLOOKUP(C30,Colaboradores!$E$2:$G$33,2,FALSE) -> #N/A
A31: =B31&COUNTIF($B$2:B31,B31) -> 3 - ISOLANTE OU FELTRO8 | B31: 3 - ISOLANTE OU FELTRO | E31: =VLOOKUP(C31,Colaboradores!$E$2:$G$33,2,FALSE) -> #N/A
A32: =B32&COUNTIF($B$2:B32,B32) -> 3 - ISOLANTE OU FELTRO9 | B32: 3 - ISOLANTE OU FELTRO | E32: =VLOOKUP(C32,Colaboradores!$E$2:$G$33,2,FALSE) -> #N/A
A33: =B33&COUNTIF($B$2:B33,B33) -> 3 - ISOLANTE OU FELTRO10 | B33: 3 - ISOLANTE OU FELTRO | E33: =VLOOKUP(C33,Colaboradores!$E$2:$G$33,2,FALSE) -> #N/A
A34: =B34&COUNTIF($B$2:B34,B34) -> 3 - ISOLANTE OU FELTRO11 | B34: 3 - ISOLANTE OU FELTRO | E34: =VLOOKUP(C34,Colaboradores!$E$2:$G$33,2,FALSE) -> #N/A
A35: =B35&COUNTIF($B$2:B35,B35) -> 3 - ISOLANTE OU FELTRO12 | B35: 3 - ISOLANTE OU FELTRO | E35: =VLOOKUP(C35,Colaboradores!$E$2:$G$33,2,FALSE) -> #N/A
A36: =B36&COUNTIF($B$2:B36,B36) -> 3 - ISOLANTE OU FELTRO13 | B36: 3 - ISOLANTE OU FELTRO | E36: =VLOOKUP(C36,Colaboradores!$E$2:$G$33,2,FALSE) -> #N/A
A37: =B37&COUNTIF($B$2:B37,B37) -> 4 - TETO1 | B37: 4 - TETO | C37: DESMONTAGEM | D37: Desmontar teto e colunas | E37: Nikolas | F37: 80 | H37: 0
A38: =B38&COUNTIF($B$2:B38,B38) -> 4 - TETO2 | B38: 4 - TETO | C38: PREPARAÇÃO | D38: Remoção tecido antigo e limpeza | E38: Nikolas | F38: 240 | H38: 0
A39: =B39&COUNTIF($B$2:B39,B39) -> 4 - TETO3 | B39: 4 - TETO | C39: PREPARAÇÃO | D39: Limpeza das colunas originais | E39: Nikolas | F39: 60 | H39: 0
A40: =B40&COUNTIF($B$2:B40,B40) -> 4 - TETO4 | B40: 4 - TETO | C40: CORTE | D40: Corte do novo tecido | E40: =VLOOKUP(C40,Colaboradores!$E$2:$G$33,2,FALSE) -> Rita | F40: 15 | H40: 0
...

Sheet Colaboradores
A1: Colaboradores | C1: x | E1: Setor | F1: Colaborador Dedicado | G1: Colaboradores Primários para Execução
A2: Kadu | E2: APLICAÇÃO COLA | F2: Lohan | G2: Lohan/Kadu/Nikolas
A3: Edna | E3: APLICAÇÃO COLA | F3: Kadu | G3: Lohan/Kadu/Nikolas
A4: Gabriel | E4: APLICAÇÃO COLA | F4: Nikolas | G4: Lohan/Kadu/Nikolas
A5: Lohan | E5: COLAGEM | F5: Gabriel | G5: Gabriel
A6: Arthur | E6: CORTE | F6: Rita | G6: Lohan/Kadu/Nikolas
A7: Nikolas | E7: COSTURA | F7: Edna | G7: Edna
A8: Brea | E8: DESMONTAGEM | F8: Nikolas | G8: Lohan/Kadu/Nikolas
A9: Paulique | E9: DESMONTAGEM | F9: Lohan | G9: Lohan/Kadu/Nikolas
A10: Rita | E10: DESMONTAGEM | F10: Kadu | G10: Lohan/Kadu/Nikolas
A11: Marcio | E11: ESPUMA | F11: Kadu | G11: Lohan/Kadu/Nikolas/Arthur
A12: Rapucci | E12: ESPUMA | F12: Lohan | G12: Lohan/Kadu/Nikolas/Arthur
E13: ESPUMA | F13: Arthur | G13: Lohan/Kadu/Nikolas/Arthur
E14: ESPUMA | F14: Nikolas | G14: Lohan/Kadu/Nikolas/Arthur
E15: FINALIZAÇÃO | F15: Arthur | G15: Arthur/Gabriel
E16: FINALIZAÇÃO | F16: Gabriel | G16: Arthur/Gabriel
E17: LIMPEZA | F17: Nikolas | G17: Lohan/Kadu/Nikolas
E18: LIMPEZA | F18: Lohan | G18: Lohan/Kadu/Nikolas
E19: LIMPEZA | F19: Kadu | G19: Lohan/Kadu/Nikolas
E20: MODELAGEM | F20: Arthur | G20: Rita/Arthur
E21: MODELAGEM | F21: Rita | G21: Rita/Arthur
E22: MONTAGEM | F22: Arthur | G22: Arthur/Gabriel
E23: MONTAGEM | F23: Gabriel | G23: Arthur/Gabriel
E24: PINTURA | F24: Paulique | G24: Paulique
... E33: MARCENARIA | F33: Brea | G33: Brea

Sheet PRG01
G1: TAREFA | H1: SETOR | I1: ATIVIDADE | J1: ATRIBUÍDO PARA | K1: Minutos | L1: Horas
F2: 1 | G2: {=IFERROR(VLOOKUP(GERENCIAMENTO!$D$23&ROW(A1),'ATIVIDADES E APONTAMENTOS'!$A:$F,{2,3,4,5,6},0),"Não Executar")} -> 1 - RETIRADA DE PEÇAS DO VEÍCULO/BALCÃO | H2: DESMONTAGEM | I2: Verificar se não tem nenhuma peça quebrada ou faltante, riscos externos e internos (Checklist durante desmontagem (Foto/Filmagem) | J2: Kadu | K2: 15 | L2: =K2/60 -> 0.25
F3: 2 | G3: {=IFERROR(VLOOKUP(GERENCIAMENTO!$D$23&ROW(A2),'ATIVIDADES E APONTAMENTOS'!$A:$F,{2,3,4,5,6},0),"Não Executar")} -> 1 - RETIRADA DE PEÇAS DO VEÍCULO/BALCÃO | H3: DESMONTAGEM | I3: Retirada do volante (se necessário) | J3: Kadu | K3: 20 | L3: =K3/60 -> 0.33333333
F4: 3 | G4: {=IFERROR(VLOOKUP(GERENCIAMENTO!$D$23&ROW(A3),'ATIVIDADES E APONTAMENTOS'!$A:$F,{2,3,4,5,6},0),"Não Executar")} -> 1 - RETIRADA DE PEÇAS DO VEÍCULO/BALCÃO | H4: DESMONTAGEM | I4: Retirar bancos D/T | J4: Kadu | K4: 10 | L4: =K4/60 -> 0.16666667
F5: 4 | G5: {=IFERROR(VLOOKUP(GERENCIAMENTO!$D$23&ROW(A4),'ATIVIDADES E APONTAMENTOS'!$A:$F,{2,3,4,5,6},0),"Não Executar")} -> 1 - RETIRADA DE PEÇAS DO VEÍCULO/BALCÃO | H5: DESMONTAGEM | I5: Retirar Laterais D/T + Ombreiras | J5: Brea | K5: 15 | L5: =K5/60 -> 0.25
F6: 5 | G6: {=IFERROR(VLOOKUP(GERENCIAMENTO!$D$23&ROW(A5),'ATIVIDADES E APONTAMENTOS'!$A:$F,{2,3,4,5,6},0),"Não Executar")} -> 1 - RETIRADA DE PEÇAS DO VEÍCULO/BALCÃO | H6: DESMONTAGEM | I6: Retirar console + carpete do assoalho | J6: Nikolas | K6: 40 | L6: =K6/60 -> 0.66666667
F7: 6 | G7: {=IFERROR(VLOOKUP(GERENCIAMENTO!$D$23&ROW(A6),'ATIVIDADES E APONTAMENTOS'!$A:$F,{2,3,4,5,6},0),"Não Executar")} -> 1 - RETIRADA DE PEÇAS DO VEÍCULO/BALCÃO | H7: DESMONTAGEM | I7: Retirada da lateral do porta-malas | J7: Nikolas | K7: 15 | L7: =K7/60 -> 0.25
F8: 7 | G8: {=IFERROR(VLOOKUP(GERENCIAMENTO!$D$23&ROW(A7),'ATIVIDADES E APONTAMENTOS'!$A:$F,{2,3,4,5,6},0),"Não Executar")} -> 1 - RETIRADA DE PEÇAS DO VEÍCULO/BALCÃO | H8: DESMONTAGEM | I8: Retirada do carpete da caixa de rodas +chão do porta-malas e prateleiras do tampão. | J8: Nikolas | K8: 30 | L8: =K8/60 -> 0.5
F9: 8 | G9: {=IFERROR(VLOOKUP(GERENCIAMENTO!$D$23&ROW(A8),'ATIVIDADES E APONTAMENTOS'!$A:$F,{2,3,4,5,6},0),"Não Executar")} -> 1 - RETIRADA DE PEÇAS DO VEÍCULO/BALCÃO | H9: DESMONTAGEM | I9: Retirada do teto + acessórios e colunas. | J9: Nikolas | K9: 60 | L9: =K9/60 -> 1
F10: 9 | G10: {=IFERROR(VLOOKUP(GERENCIAMENTO!$D$23&ROW(A9),'ATIVIDADES E APONTAMENTOS'!$A:$F,{2,3,4,5,6},0),"Não Executar")} -> 1 - RETIRADA DE PEÇAS DO VEÍCULO/BALCÃO | H10: 0 | I10: 0 | J10: Não Executar | K10: 0 | L10: =K10/60 -> 0
F11: 10 | G11: {=IFERROR(VLOOKUP(GERENCIAMENTO!$D$23&ROW(A10),'ATIVIDADES E APONTAMENTOS'!$A:$F,{2,3,4,5,6},0),"Não Executar")} -> 1 - RETIRADA DE PEÇAS DO VEÍCULO/BALCÃO | H11: 0 | I11: 0 | J11: Não Executar | K11: 0 | L11: =K11/60 -> 0
F12: 11 | G12: {=IFERROR(VLOOKUP(GERENCIAMENTO!$D$23&ROW(A11),'ATIVIDADES E APONTAMENTOS'!$A:$F,{2,3,4,5,6},0),"Não Executar")} -> 1 - RETIRADA DE PEÇAS DO VEÍCULO/BALCÃO | H12: 0 | I12: 0 | J12: Não Executar | K12: 0 | L12: =K12/60 -> 0
F13: 12 | G13: {=IFERROR(VLOOKUP(GERENCIAMENTO!$D$23&ROW(A12),'ATIVIDADES E APONTAMENTOS'!$A:$F,{2,3,4,5,6},0),"Não Executar")} -> 1 - RETIRADA DE PEÇAS DO VEÍCULO/BALCÃO | H13: 0 | I13: 0 | J13: Não Executar | K13: 0 | L13: =K13/60 -> 0
F14: 13 | G14: {=IFERROR(VLOOKUP(GERENCIAMENTO!$D$23&ROW(A13),'ATIVIDADES E APONTAMENTOS'!$A:$F,{2,3,4,5,6},0),"Não Executar")} -> 1 - RETIRADA DE PEÇAS DO VEÍCULO/BALCÃO | H14: 0 | I14: 0 | J14: Não Executar | K14: 0 | L14: =K14/60 -> 0
F15: 14 | G15: {=IFERROR(VLOOKUP(GERENCIAMENTO!$D$23&ROW(A14),'ATIVIDADES E APONTAMENTOS'!$A:$F,{2,3,4,5,6},0),"Não Executar")} -> 1 - RETIRADA DE PEÇAS DO VEÍCULO/BALCÃO | H15: 0 | I15: 0 | J15: Não Executar | K15: 0 | L15: =K15/60 -> 0
F16: 15 | G16: {=IFERROR(VLOOKUP(GERENCIAMENTO!$D$23&ROW(A15),'ATIVIDADES E APONTAMENTOS'!$A:$F,{2,3,4,5,6},0),"Não Executar")} -> Não Executar | L16: =K16/60 -> 0
F17: 16 | G17: {=IFERROR(VLOOKUP(GERENCIAMENTO!$D$23&ROW(A16),'ATIVIDADES E APONTAMENTOS'!$A:$F,{2,3,4,5,6},0),"Não Executar")} -> Não Executar | L17: =K17/60 -> 0
F18: 17 | G18: {=IFERROR(VLOOKUP(GERENCIAMENTO!$D$23&ROW(A17),'ATIVIDADES E APONTAMENTOS'!$A:$F,{2,3,4,5,6},0),"Não Executar")} -> Não Executar | L18: =K18/60 -> 0
F19: 18 | G19: {=IFERROR(VLOOKUP(GERENCIAMENTO!$D$23&ROW(A18),'ATIVIDADES E APONTAMENTOS'!$A:$F,{2,3,4,5,6},0),"Não Executar")} -> Não Executar | L19: =K19/60 -> 0
F20: 19 | G20: {=IFERROR(VLOOKUP(GERENCIAMENTO!$D$23&ROW(A19),'ATIVIDADES E APONTAMENTOS'!$A:$F,{2,3,4,5,6},0),"Não Executar")} -> Não Executar | L20: =K20/60 -> 0
F21: 20 | G21: {=IFERROR(VLOOKUP(GERENCIAMENTO!$D$23&ROW(A20),'ATIVIDADES E APONTAMENTOS'!$A:$F,{2,3,4,5,6},0),"Não Executar")} -> Não Executar | L21: =K21/60 -> 0
F22: 21 | G22: {=IFERROR(VLOOKUP(GERENCIAMENTO!$D$23&ROW(A21),'ATIVIDADES E APONTAMENTOS'!$A:$F,{2,3,4,5,6},0),"Não Executar")} -> Não Executar | L22: =K22/60 -> 0
F23: 22 | G23: {=IFERROR(VLOOKUP(GERENCIAMENTO!$D$23&ROW(A22),'ATIVIDADES E APONTAMENTOS'!$A:$F,{2,3,4,5,6},0),"Não Executar")} -> Não Executar | L23: =K23/60 -> 0
F24: 23 | G24: {=IFERROR(VLOOKUP(GERENCIAMENTO!$D$23&ROW(A23),'ATIVIDADES E APONTAMENTOS'!$A:$F,{2,3,4,5,6},0),"Não Executar")} -> Não Executar | L24: =K24/60 -> 0
F25: 24 | G25: {=IFERROR(VLOOKUP(GERENCIAMENTO!$D$23&ROW(A24),'ATIVIDADES E APONTAMENTOS'!$A:$F,{2,3,4,5,6},0),"Não Executar")} -> Não Executar | L25: =K25/60 -> 0
F26: 25 | G26: {=IFERROR(VLOOKUP(GERENCIAMENTO!$D$23&ROW(A25),'ATIVIDADES E APONTAMENTOS'!$A:$F,{2,3,4,5,6},0),"Não Executar")} -> Não Executar | L26: =K26/60 -> 0
F27: 1 | G27: {=IFERROR(VLOOKUP(GERENCIAMENTO!$D$24&ROW(A1),'ATIVIDADES E APONTAMENTOS'!$A:$F,{2,3,4,5,6},0),"Não Executar")} -> 2 - LIMPEZA INICIAL | H27: PREPARAÇÃO | I27: Aspiração detalhada | J27: Lohan | K27: 25 | L27: =K27/60 -> 0.41666667
F28: 2 | G28: {=IFERROR(VLOOKUP(GERENCIAMENTO!$D$24&ROW(A2),'ATIVIDADES E APONTAMENTOS'!$A:$F,{2,3,4,5,6},0),"Não Executar")} -> 2 - LIMPEZA INICIAL | H28: 0 | I28: 0 | J28: Não Executar | K28: 0 | L28: =K28/60 -> 0
F29: 3 | G29: {=IFERROR(VLOOKUP(GERENCIAMENTO!$D$24&ROW(A3),'ATIVIDADES E APONTAMENTOS'!$A:$F,{2,3,4,5,6},0),"Não Executar")} -> 2 - LIMPEZA INICIAL | H29: 0 | I29: 0 | J29: Não Executar | K29: 0 | L29: =K29/60 -> 0
F30: 4 | G30: {=IFERROR(VLOOKUP(GERENCIAMENTO!$D$24&ROW(A4),'ATIVIDADES E APONTAMENTOS'!$A:$F,{2,3,4,5,6},0),"Não Executar")} -> 2 - LIMPEZA INICIAL | H30: 0 | I30: 0 | J30: Não Executar | K30: 0 | L30: =K30/60 -> 0
F31: 5 | G31: {=IFERROR(VLOOKUP(GERENCIAMENTO!$D$24&ROW(A5),'ATIVIDADES E APONTAMENTOS'!$A:$F,{2,3,4,5,6},0),"Não Executar")} -> 2 - LIMPEZA INICIAL | H31: 0 | I31: 0 | J31: Não Executar | K31: 0 | L31: =K31/60 -> 0
F32: 6 | G32: {=IFERROR(VLOOKUP(GERENCIAMENTO!$D$24&ROW(A6),'ATIVIDADES E APONTAMENTOS'!$A:$F,{2,3,4,5,6},0),"Não Executar")} -> 2 - LIMPEZA INICIAL | H32: 0 | I32: 0 | J32: Não Executar | K32: 0 | L32: =K32/60 -> 0
F33: 7 | G33: {=IFERROR(VLOOKUP(GERENCIAMENTO!$D$24&ROW(A7),'ATIVIDADES E APONTAMENTOS'!$A:$F,{2,3,4,5,6},0),"Não Executar")} -> 2 - LIMPEZA INICIAL | H33: 0 | I33: 0 | J33: Não Executar | K33: 0 | L33: =K33/60 -> 0
F34: 8 | G34: {=IFERROR(VLOOKUP(GERENCIAMENTO!$D$24&ROW(A8),'ATIVIDADES E APONTAMENTOS'!$A:$F,{2,3,4,5,6},0),"Não Executar")} -> 2 - LIMPEZA INICIAL | H34: 0 | I34: 0 | J34: Não Executar | K34: 0 | L34: =K34/60 -> 0
F35: 9 | G35: {=IFERROR(VLOOKUP(GERENCIAMENTO!$D$24&ROW(A9),'ATIVIDADES E APONTAMENTOS'!$A:$F,{2,3,4,5,6},0),"Não Executar")} -> Não Executar | L35: =K35/60 -> 0
F36: 10 | G36: {=IFERROR(VLOOKUP(GERENCIAMENTO!$D$24&ROW(A10),'ATIVIDADES E APONTAMENTOS'!$A:$F,{2,3,4,5,6},0),"Não Executar")} -> Não Executar | L36: =K36/60 -> 0
F37: 11 | G37: {=IFERROR(VLOOKUP(GERENCIAMENTO!$D$24&ROW(A11),'ATIVIDADES E APONTAMENTOS'!$A:$F,{2,3,4,5,6},0),"Não Executar")} -> Não Executar | L37: =K37/60 -> 0
F38: 12 | G38: {=IFERROR(VLOOKUP(GERENCIAMENTO!$D$24&ROW(A12),'ATIVIDADES E APONTAMENTOS'!$A:$F,{2,3,4,5,6},0),"Não Executar")} -> Não Executar | L38: =K38/60 -> 0
F39: 13 | G39: {=IFERROR(VLOOKUP(GERENCIAMENTO!$D$24&ROW(A13),'ATIVIDADES E APONTAMENTOS'!$A:$F,{2,3,4,5,6},0),"Não Executar")} -> Não Executar | L39: =K39/60 -> 0
F40: 14 | G40: {=IFERROR(VLOOKUP(GERENCIAMENTO!$D$24&ROW(A14),'ATIVIDADES E APONTAMENTOS'!$A:$F,{2,3,4,5,6},0),"Não Executar")} -> Não Executar | L40: =K40/60 -> 0
...

Sheet PRG02
A3: Rótulos de Linha | B3: H Real | C3: Média de % Conclusão | D3: Média de Campo2
A4: 1 - RETIRADA DE PEÇAS DO VEÍCULO/BALCÃO | B4: 8.5833333 | C4: 0.8875 | D4: 2.5121951
A5: 2 - LIMPEZA INICIAL | B5: 0.83333333 | C5: 1 | D5: 2
A6: 3 - ISOLANTE OU FELTRO | B6: 1.5 | C6: 0 | D6: 0.26086957
A7: 4 - TETO | B7: 0 | C7: 0 | D7: 0
A8: 5 - CINTOS | B8: 0 | C8: 0 | D8: 0
A9: 6 - CARPETE / ASSOALHO ( NOVO ? / MOLDADO ? / PORSCHE ?) | B9: 0 | C9: 0 | D9: 0
A10: 7 - CONSOLE CENTRAL + PEÇAS | B10: 0 | C10: 0 | D10: 0
A11: 8 - PORTA MALAS | B11: 0 | C11: 0 | D11: 0
A12: 9 - TAMPA TRASEIRA | B12: 0 | C12: 0 | D12: 0
A13: 10 - LATERAIS TRASEIRAS | B13: 0 | C13: 0 | D13: 0
A14: 11 - OMBREIRA | B14: 0 | C14: 0 | D14: 0
A15: 12 - FORROS DE PORTAS | B15: 0 | C15: 0 | D15: 0
... A24: Total Geral | B24: 10.916667 | C24: 0.060902256 | D24: 0.13804004
